<mujoco model="ur3e scene">
  <compiler angle="radian" meshdir="assets/"/>

  <option timestep="0.001"/>

  <size nkey="1"/>

  <visual>
    <global azimuth="120" elevation="-20"/>
    <headlight diffuse="0.6 0.6 0.6" specular="0 0 0"/>
    <rgba haze="0.15 0.25 0.35 1"/>
  </visual>

  <statistic extent="0.8" center="0.3 0 0.4"/>

  <default>
    <default class="ur3e">
      <material shininess="0.25"/>
      <joint range="-6.28319 6.28319" armature="0.1"/>
      <site size="0.001 0.005 0.005" group="4" rgba="0.5 0.5 0.5 0.3"/>
      <general ctrlrange="-6.2831 6.2831" forcerange="-56 56" biastype="affine" gainprm="1000" biasprm="0 -1000 -200"/>
      <default class="size2">
        <joint damping="2"/>
      </default>
      <default class="size1">
        <general forcerange="-28 28" gainprm="500" biasprm="0 -500 -100"/>
      </default>
      <default class="size0">
        <general forcerange="-12 12" gainprm="250" biasprm="0 -250 -50"/>
      </default>
      <default class="visual">
        <geom type="mesh" contype="0" conaffinity="0" group="2"/>
      </default>
      <default class="collision">
        <geom type="capsule" group="3"/>
        <default class="eef_collision">
          <geom type="cylinder"/>
        </default>
      </default>
    </default>
  </default>

  <asset>
    <texture type="skybox" colorspace="auto" builtin="gradient" rgb1="0.3 0.5 0.7" rgb2="0 0 0" width="512" height="3072"/>
    <texture type="2d" colorspace="auto" name="groundplane" builtin="checker" mark="edge" rgb1="0.2 0.3 0.4" rgb2="0.1 0.2 0.3" markrgb="0.8 0.8 0.8" width="300" height="300"/>
    <material name="black" class="ur3e" rgba="0.033 0.033 0.033 1"/>
    <material name="jointgray" class="ur3e" rgba="0.278 0.278 0.278 1"/>
    <material name="linkgray" class="ur3e" rgba="0.82 0.82 0.82 1"/>
    <material name="urblue" class="ur3e" rgba="0.49 0.678 0.8 1"/>
    <material name="groundplane" texture="groundplane" texuniform="true" texrepeat="5 5" reflectance="0.2"/>
    <mesh name="base_0" content_type="model/obj" file="base_0.obj"/>
    <mesh name="base_1" content_type="model/obj" file="base_1.obj"/>
    <mesh name="forearm_0" content_type="model/obj" file="forearm_0.obj"/>
    <mesh name="forearm_1" content_type="model/obj" file="forearm_1.obj"/>
    <mesh name="forearm_2" content_type="model/obj" file="forearm_2.obj"/>
    <mesh name="forearm_3" content_type="model/obj" file="forearm_3.obj"/>
    <mesh name="forearm_4" content_type="model/obj" file="forearm_4.obj"/>
    <mesh name="forearm_5" content_type="model/obj" file="forearm_5.obj"/>
    <mesh name="forearm_6" content_type="model/obj" file="forearm_6.obj"/>
    <mesh name="shoulder_0" content_type="model/obj" file="shoulder_0.obj"/>
    <mesh name="shoulder_1" content_type="model/obj" file="shoulder_1.obj"/>
    <mesh name="shoulder_2" content_type="model/obj" file="shoulder_2.obj"/>
    <mesh name="upperarm_0" content_type="model/obj" file="upperarm_0.obj"/>
    <mesh name="upperarm_1" content_type="model/obj" file="upperarm_1.obj"/>
    <mesh name="upperarm_2" content_type="model/obj" file="upperarm_2.obj"/>
    <mesh name="upperarm_3" content_type="model/obj" file="upperarm_3.obj"/>
    <mesh name="upperarm_4" content_type="model/obj" file="upperarm_4.obj"/>
    <mesh name="upperarm_5" content_type="model/obj" file="upperarm_5.obj"/>
    <mesh name="upperarm_6" content_type="model/obj" file="upperarm_6.obj"/>
    <mesh name="upperarm_7" content_type="model/obj" file="upperarm_7.obj"/>
    <mesh name="upperarm_8" content_type="model/obj" file="upperarm_8.obj"/>
    <mesh name="wrist1_0" content_type="model/obj" file="wrist1_0.obj"/>
    <mesh name="wrist1_1" content_type="model/obj" file="wrist1_1.obj"/>
    <mesh name="wrist1_2" content_type="model/obj" file="wrist1_2.obj"/>
    <mesh name="wrist2_0" content_type="model/obj" file="wrist2_0.obj"/>
    <mesh name="wrist2_1" content_type="model/obj" file="wrist2_1.obj"/>
    <mesh name="wrist2_2" content_type="model/obj" file="wrist2_2.obj"/>
    <mesh name="wrist3" content_type="model/obj" file="wrist3.obj"/>
  </asset>

  <worldbody>
    <geom name="floor" size="0 0 0.05" type="plane" material="groundplane"/>
    <light name="top" pos="0 0 1" dir="0 0 -1"/>
    <light pos="0 0 1.5" dir="0 0 -1" type="directional"/>
    <body name="base" childclass="ur3e">
      <inertial pos="0 0 0" mass="4" diaginertia="0.00443333 0.00443333 0.0072"/>
      <geom class="visual" pos="0 0 0" quat="0.707107 0.707107 0 0" material="black" mesh="base_0"/>
      <geom class="visual" quat="0.707107 0.707107 0 0" material="jointgray" mesh="base_1"/>
      <body name="shoulder_link" pos="0 0 0.15185">
        <inertial pos="0 0 0" mass="2" diaginertia="0.00809316 0.00809316 0.005625"/>
        <joint name="robot0:shoulder_pan_joint" class="size2" pos="0 0 0" axis="0 0 1"/>
        <geom class="visual" pos="0 0 0" quat="0.707107 0.707107 0 0" material="black" mesh="shoulder_0"/>
        <geom class="visual" quat="0.707107 0.707107 0 0" material="urblue" mesh="shoulder_1"/>
        <geom class="visual" quat="0.707107 0.707107 0 0" material="jointgray" mesh="shoulder_2"/>
        <geom class="collision" size="0.055 0.055" pos="0 0 -0.03"/>
        <body name="upper_arm_link" pos="0 0.12 0" quat="0.707107 0 0.707107 0">
          <inertial pos="-0.121825 0 0.12" quat="0.707107 0 0.707107 0" mass="3.42" diaginertia="0.0217285 0.0217285 0.00961875"/>
          <joint name="robot0:shoulder_lift_joint" class="size2" pos="0 0 0" axis="0 1 0"/>
          <geom class="visual" quat="0.707107 0.707107 0 0" material="urblue" mesh="upperarm_0"/>
          <geom class="visual" quat="0.707107 0.707107 0 0" material="jointgray" mesh="upperarm_1"/>
          <geom class="visual" quat="0.707107 0.707107 0 0" material="black" mesh="upperarm_2"/>
          <geom class="visual" pos="0 0 0" quat="0.707107 0.707107 0 0" material="linkgray" mesh="upperarm_3"/>
          <geom class="visual" pos="0 0 0" quat="0.707107 0.707107 0 0" material="black" mesh="upperarm_4"/>
          <geom class="visual" pos="0 0 0" quat="0.707107 0.707107 0 0" material="urblue" mesh="upperarm_5"/>
          <geom class="visual" pos="0 0 0" quat="0.707107 0.707107 0 0" material="black" mesh="upperarm_6"/>
          <geom class="visual" pos="0 0 0" quat="0.707107 0.707107 0 0" material="jointgray" mesh="upperarm_7"/>
          <geom class="visual" pos="0 0 0" quat="0.707107 0.707107 0 0" material="black" mesh="upperarm_8"/>
          <geom class="collision" size="0.055 0.055" pos="0 -0.03 0" quat="0.707107 0.707107 0 0"/>
          <geom class="collision" size="0.05 0.1" pos="0 0 0.15"/>
          <body name="forearm_link" pos="0 -0.0921 0.24355">
            <inertial pos="-0.1066 0 0.027" quat="0.707107 0 0.707107 0" mass="1.43" diaginertia="0.00654457 0.00654457 0.00354375"/>
            <joint name="robot0:elbow_joint" class="size1" pos="0 0 0" axis="0 1 0" range="-3.14159 3.14159"/>
            <geom class="visual" quat="0.707107 0.707107 0 0" material="jointgray" mesh="forearm_0"/>
            <geom class="visual" quat="0.707107 0.707107 0 0" material="black" mesh="forearm_1"/>
            <geom class="visual" pos="0 0 0" quat="0.707107 0.707107 0 0" material="linkgray" mesh="forearm_2"/>
            <geom class="visual" pos="0 0 0" quat="0.707107 0.707107 0 0" material="black" mesh="forearm_3"/>
            <geom class="visual" pos="0 0 0" quat="0.707107 0.707107 0 0" material="urblue" mesh="forearm_4"/>
            <geom class="visual" pos="0 0 0" quat="0.707107 0.707107 0 0" material="black" mesh="forearm_5"/>
            <geom class="visual" pos="0 0 0" quat="0.707107 0.707107 0 0" material="jointgray" mesh="forearm_6"/>
            <geom class="collision" size="0.045 0.045" pos="0 0.08 0" quat="0.707107 0.707107 0 0"/>
            <geom class="collision" size="0.04 0.1" pos="0 0 0.1"/>
            <body name="wrist_1_link" pos="0 0 0.2132" quat="0.707107 0 0.707107 0">
              <inertial pos="0 0 0" quat="0.5 0.5 -0.5 0.5" mass="0.8" diaginertia="0.00225 0.002085 0.002085"/>
              <joint name="robot0:wrist_1_joint" class="size0" pos="0 0 0" axis="0 1 0"/>
              <geom class="visual" pos="0 0 0" quat="0.707107 0.707107 0 0" material="urblue" mesh="wrist1_0"/>
              <geom class="visual" pos="0 0 0" quat="0.707107 0.707107 0 0" material="jointgray" mesh="wrist1_1"/>
              <geom class="visual" pos="0 0 0" quat="0.707107 0.707107 0 0" material="black" mesh="wrist1_2"/>
              <geom class="collision" size="0.04 0.07" pos="0 0.05 0" quat="0.707107 0.707107 0 0"/>
              <body name="wrist_2_link" pos="0 0.104 0">
                <inertial pos="0 0 0" quat="0.5 0.5 -0.5 0.5" mass="0.8" diaginertia="0.00225 0.002085 0.002085"/>
                <joint name="robot0:wrist_2_joint" class="size0" pos="0 0 0" axis="0 0 1"/>
                <geom class="visual" quat="0.707107 0.707107 0 0" material="jointgray" mesh="wrist2_0"/>
                <geom class="visual" pos="0 0 0" quat="0.707107 0.707107 0 0" material="black" mesh="wrist2_1"/>
                <geom class="visual" pos="0 0 0" quat="0.707107 0.707107 0 0" material="urblue" mesh="wrist2_2"/>
                <geom class="collision" size="0.04 0.06" pos="0 0 0.04"/>
                <geom class="collision" size="0.038 0.045" pos="0 0.026 0.085" quat="0.707107 0.707107 0 0"/>
                <body name="wrist_3_link" pos="0 0 0.085">
                  <inertial pos="0 0 -0.02" quat="0.5 0.5 -0.5 0.5" mass="0.26" diaginertia="0.0001792 0.000136267 0.000136267"/>
                  <joint name="robot0:wrist_3_joint" class="size0" pos="0 0 0" axis="0 1 0"/>
                  <geom class="visual" pos="0 0 0" quat="0.707107 0.707107 0 0" material="linkgray" mesh="wrist3"/>
                  <geom class="eef_collision" size="0.04 0.02" pos="0 0.08 0" quat="0.707107 0.707107 0 0"/>
                  <site name="attachment_site" pos="0 0.1 0" quat="-0.707107 0.707107 0 0"/>
                </body>
              </body>
            </body>
          </body>
        </body>
      </body>
    </body>
  </worldbody>

  <actuator>
    <general name="shoulder_pan" class="size2" joint="robot0:shoulder_pan_joint"/>
    <general name="shoulder_lift" class="size2" joint="robot0:shoulder_lift_joint"/>
    <general name="elbow" class="size1" joint="robot0:elbow_joint"/>
    <general name="wrist_1" class="size0" joint="robot0:wrist_1_joint"/>
    <general name="wrist_2" class="size0" joint="robot0:wrist_2_joint"/>
    <general name="wrist_3" class="size0" joint="robot0:wrist_3_joint"/>
  </actuator>

  <keyframe>
    <key name="home" qpos="-1.5708 -1.5708 1.5708 -1.5708 -1.5708 0" ctrl="-1.5708 -1.5708 1.5708 -1.5708 -1.5708 0"/>
  </keyframe>
</mujoco>
