<mujoco model="ur3e scene">
  <compiler angle="radian" meshdir="assets/"/>

  <option timestep="0.001"/>

  <size nkey="2"/>

  <visual>
    <global azimuth="120" elevation="-20"/>
    <headlight diffuse="0.6 0.6 0.6" specular="0 0 0"/>
    <rgba haze="0.15 0.25 0.35 1"/>
  </visual>

  <statistic extent="0.8" center="0.3 0 0.4"/>

  <default>
    <default class="ur3e">
      <material shininess="0.25"/>
      <joint range="-6.28319 6.28319" armature="0.1"/>
      <site size="0.001 0.005 0.005" group="4" rgba="0.5 0.5 0.5 0.3"/>
      <general ctrlrange="-6.2831 6.2831" forcerange="-56 56" biastype="affine" gainprm="1000" biasprm="0 -1000 -200"/>
      <default class="size2">
        <joint damping="2"/>
      </default>
      <default class="size1">
        <general forcerange="-28 28" gainprm="500" biasprm="0 -500 -100"/>
      </default>
      <default class="size0">
        <general forcerange="-12 12" gainprm="250" biasprm="0 -250 -50"/>
      </default>
      <default class="visual">
        <geom type="mesh" contype="0" conaffinity="0" group="2"/>
      </default>
      <default class="collision">
        <geom type="capsule" group="3"/>
        <default class="eef_collision">
          <geom type="cylinder"/>
        </default>
      </default>
    </default>
    <default class="wrist_3_linkmaingripper">
      <default class="wrist_3_link2f140gripper">
        <material specular="0.7" shininess="0.4"/>
        <general biastype="affine"/>
        <default class="wrist_3_linkdrivergripper">
          <joint solreflimit="0.005" solimplimit="0.95 0.99" range="-0.8 0" armature="0.005" damping="0.1"/>
        </default>
        <default class="wrist_3_linkfollowergripper">
          <joint solreflimit="0.005" solimplimit="0.95 0.99" range="-0.8757 0.8757" armature="0.001"/>
        </default>
        <default class="wrist_3_linkspring_linkgripper">
          <joint springref="-25.62" stiffness="0.05" range="-0.8 0.296706" armature="0.001" damping="0.00125"/>
        </default>
        <default class="wrist_3_linkcouplergripper">
          <joint solreflimit="0.005" solimplimit="0.95 0.99" range="0 1.57" armature="0.001"/>
        </default>
        <default class="wrist_3_linkvisualgripper">
          <geom type="mesh" contype="0" conaffinity="0" group="2"/>
        </default>
        <default class="wrist_3_linkcollisiongripper">
          <geom type="mesh" group="3"/>
          <default class="wrist_3_linkpad_box1gripper">
            <geom size="0.0135 0.0325 0.00375" type="box" priority="1" friction="0.7" solref="0.004" solimp="0.95 0.99" rgba="0.55 0.55 0.55 1"/>
          </default>
        </default>
      </default>
    </default>
  </default>

  <asset>
    <texture type="skybox" colorspace="auto" builtin="gradient" rgb1="0.3 0.5 0.7" rgb2="0 0 0" width="512" height="3072"/>
    <texture type="2d" colorspace="auto" name="groundplane" builtin="checker" mark="edge" rgb1="0.2 0.3 0.4" rgb2="0.1 0.2 0.3" markrgb="0.8 0.8 0.8" width="300" height="300"/>
    <texture type="skybox" colorspace="auto" builtin="gradient" rgb1="0.3 0.5 0.7" rgb2="0 0 0" width="512" height="3072"/>
    <texture type="2d" colorspace="auto" name="wrist_3_linkgroundplanegripper" builtin="checker" mark="edge" rgb1="0.2 0.3 0.4" rgb2="0.1 0.2 0.3" markrgb="0.8 0.8 0.8" width="300" height="300"/>
    <material name="black" class="ur3e" rgba="0.033 0.033 0.033 1"/>
    <material name="jointgray" class="ur3e" rgba="0.278 0.278 0.278 1"/>
    <material name="linkgray" class="ur3e" rgba="0.82 0.82 0.82 1"/>
    <material name="urblue" class="ur3e" rgba="0.49 0.678 0.8 1"/>
    <material name="groundplane" texture="groundplane" texuniform="true" texrepeat="5 5" reflectance="0.2"/>
    <material name="wrist_3_linkmetalgripper" rgba="0.58 0.58 0.58 1"/>
    <material name="wrist_3_linksiliconegripper" rgba="0.1882 0.1882 0.1882 1"/>
    <material name="wrist_3_linkgraygripper" rgba="0.4627 0.4627 0.4627 1"/>
    <material name="wrist_3_linkblackgripper" rgba="0.149 0.149 0.149 1"/>
    <material name="wrist_3_linkgroundplanegripper" texture="wrist_3_linkgroundplanegripper" texuniform="true" texrepeat="5 5" reflectance="0.2"/>
    <mesh name="base_0" file="base_0.obj"/>
    <mesh name="base_1" file="base_1.obj"/>
    <mesh name="forearm_0" file="forearm_0.obj"/>
    <mesh name="forearm_1" file="forearm_1.obj"/>
    <mesh name="forearm_2" file="forearm_2.obj"/>
    <mesh name="forearm_3" file="forearm_3.obj"/>
    <mesh name="forearm_4" file="forearm_4.obj"/>
    <mesh name="forearm_5" file="forearm_5.obj"/>
    <mesh name="forearm_6" file="forearm_6.obj"/>
    <mesh name="shoulder_0" file="shoulder_0.obj"/>
    <mesh name="shoulder_1" file="shoulder_1.obj"/>
    <mesh name="shoulder_2" file="shoulder_2.obj"/>
    <mesh name="upperarm_0" file="upperarm_0.obj"/>
    <mesh name="upperarm_1" file="upperarm_1.obj"/>
    <mesh name="upperarm_2" file="upperarm_2.obj"/>
    <mesh name="upperarm_3" file="upperarm_3.obj"/>
    <mesh name="upperarm_4" file="upperarm_4.obj"/>
    <mesh name="upperarm_5" file="upperarm_5.obj"/>
    <mesh name="upperarm_6" file="upperarm_6.obj"/>
    <mesh name="upperarm_7" file="upperarm_7.obj"/>
    <mesh name="upperarm_8" file="upperarm_8.obj"/>
    <mesh name="wrist1_0" file="wrist1_0.obj"/>
    <mesh name="wrist1_1" file="wrist1_1.obj"/>
    <mesh name="wrist1_2" file="wrist1_2.obj"/>
    <mesh name="wrist2_0" file="wrist2_0.obj"/>
    <mesh name="wrist2_1" file="wrist2_1.obj"/>
    <mesh name="wrist2_2" file="wrist2_2.obj"/>
    <mesh name="wrist3" file="wrist3.obj"/>
    <mesh name="wrist_3_linkbase_mountgripper" class="wrist_3_link2f140gripper" file="base_mount.stl" scale="0.001 0.001 0.001"/>
    <mesh name="wrist_3_linkbasegripper" class="wrist_3_link2f140gripper" file="base.stl"/>
    <mesh name="wrist_3_linkdrivergripper" class="wrist_3_link2f140gripper" file="driver.stl"/>
    <mesh name="wrist_3_linkfollowergripper" class="wrist_3_link2f140gripper" file="follower.stl"/>
    <mesh name="wrist_3_linkcouplergripper" class="wrist_3_link2f140gripper" file="coupler.stl"/>
    <mesh name="wrist_3_linkpadgripper" class="wrist_3_link2f140gripper" file="pad.stl" scale="0.001 0.001 0.001"/>
    <mesh name="wrist_3_linkspring_linkgripper" class="wrist_3_link2f140gripper" file="spring_link.stl"/>
  </asset>

  <worldbody>
    <geom name="floor" size="0 0 0.05" type="plane" material="groundplane"/>
    <light name="top" pos="0 0 1" dir="0 0 -1"/>
    <light pos="0 0 1.5" dir="0 0 -1" type="directional"/>
    <body name="base" childclass="ur3e">
      <inertial pos="0 0 0" mass="4" diaginertia="0.00443333 0.00443333 0.0072"/>
      <geom class="visual" pos="0 0 0" quat="0.707107 0.707107 0 0" material="black" mesh="base_0"/>
      <geom class="visual" quat="0.707107 0.707107 0 0" material="jointgray" mesh="base_1"/>
      <body name="shoulder_link" pos="0 0 0.15185">
        <inertial pos="0 0 0" mass="2" diaginertia="0.00809316 0.00809316 0.005625"/>
        <joint name="robot0:shoulder_pan_joint" class="size2" pos="0 0 0" axis="0 0 1"/>
        <geom class="visual" pos="0 0 0" quat="0.707107 0.707107 0 0" material="black" mesh="shoulder_0"/>
        <geom class="visual" quat="0.707107 0.707107 0 0" material="urblue" mesh="shoulder_1"/>
        <geom class="visual" quat="0.707107 0.707107 0 0" material="jointgray" mesh="shoulder_2"/>
        <geom class="collision" size="0.055 0.055" pos="0 0 -0.03"/>
        <body name="upper_arm_link" pos="0 0.12 0" quat="0.707107 0 0.707107 0">
          <inertial pos="-0.121825 0 0.12" quat="0.707107 0 0.707107 0" mass="3.42" diaginertia="0.0217285 0.0217285 0.00961875"/>
          <joint name="robot0:shoulder_lift_joint" class="size2" pos="0 0 0" axis="0 1 0"/>
          <geom class="visual" quat="0.707107 0.707107 0 0" material="urblue" mesh="upperarm_0"/>
          <geom class="visual" quat="0.707107 0.707107 0 0" material="jointgray" mesh="upperarm_1"/>
          <geom class="visual" quat="0.707107 0.707107 0 0" material="black" mesh="upperarm_2"/>
          <geom class="visual" pos="0 0 0" quat="0.707107 0.707107 0 0" material="linkgray" mesh="upperarm_3"/>
          <geom class="visual" pos="0 0 0" quat="0.707107 0.707107 0 0" material="black" mesh="upperarm_4"/>
          <geom class="visual" pos="0 0 0" quat="0.707107 0.707107 0 0" material="urblue" mesh="upperarm_5"/>
          <geom class="visual" pos="0 0 0" quat="0.707107 0.707107 0 0" material="black" mesh="upperarm_6"/>
          <geom class="visual" pos="0 0 0" quat="0.707107 0.707107 0 0" material="jointgray" mesh="upperarm_7"/>
          <geom class="visual" pos="0 0 0" quat="0.707107 0.707107 0 0" material="black" mesh="upperarm_8"/>
          <geom class="collision" size="0.055 0.055" pos="0 -0.03 0" quat="0.707107 0.707107 0 0"/>
          <geom class="collision" size="0.05 0.1" pos="0 0 0.15"/>
          <body name="forearm_link" pos="0 -0.0921 0.24355">
            <inertial pos="-0.1066 0 0.027" quat="0.707107 0 0.707107 0" mass="1.43" diaginertia="0.00654457 0.00654457 0.00354375"/>
            <joint name="robot0:elbow_joint" class="size1" pos="0 0 0" axis="0 1 0" range="-3.14159 3.14159"/>
            <geom class="visual" quat="0.707107 0.707107 0 0" material="jointgray" mesh="forearm_0"/>
            <geom class="visual" quat="0.707107 0.707107 0 0" material="black" mesh="forearm_1"/>
            <geom class="visual" pos="0 0 0" quat="0.707107 0.707107 0 0" material="linkgray" mesh="forearm_2"/>
            <geom class="visual" pos="0 0 0" quat="0.707107 0.707107 0 0" material="black" mesh="forearm_3"/>
            <geom class="visual" pos="0 0 0" quat="0.707107 0.707107 0 0" material="urblue" mesh="forearm_4"/>
            <geom class="visual" pos="0 0 0" quat="0.707107 0.707107 0 0" material="black" mesh="forearm_5"/>
            <geom class="visual" pos="0 0 0" quat="0.707107 0.707107 0 0" material="jointgray" mesh="forearm_6"/>
            <geom class="collision" size="0.045 0.045" pos="0 0.08 0" quat="0.707107 0.707107 0 0"/>
            <geom class="collision" size="0.04 0.1" pos="0 0 0.1"/>
            <body name="wrist_1_link" pos="0 0 0.2132" quat="0.707107 0 0.707107 0">
              <inertial pos="0 0 0" quat="0.5 0.5 -0.5 0.5" mass="0.8" diaginertia="0.00225 0.002085 0.002085"/>
              <joint name="robot0:wrist_1_joint" class="size0" pos="0 0 0" axis="0 1 0"/>
              <geom class="visual" pos="0 0 0" quat="0.707107 0.707107 0 0" material="urblue" mesh="wrist1_0"/>
              <geom class="visual" pos="0 0 0" quat="0.707107 0.707107 0 0" material="jointgray" mesh="wrist1_1"/>
              <geom class="visual" pos="0 0 0" quat="0.707107 0.707107 0 0" material="black" mesh="wrist1_2"/>
              <geom class="collision" size="0.04 0.07" pos="0 0.05 0" quat="0.707107 0.707107 0 0"/>
              <body name="wrist_2_link" pos="0 0.104 0">
                <inertial pos="0 0 0" quat="0.5 0.5 -0.5 0.5" mass="0.8" diaginertia="0.00225 0.002085 0.002085"/>
                <joint name="robot0:wrist_2_joint" class="size0" pos="0 0 0" axis="0 0 1"/>
                <geom class="visual" quat="0.707107 0.707107 0 0" material="jointgray" mesh="wrist2_0"/>
                <geom class="visual" pos="0 0 0" quat="0.707107 0.707107 0 0" material="black" mesh="wrist2_1"/>
                <geom class="visual" pos="0 0 0" quat="0.707107 0.707107 0 0" material="urblue" mesh="wrist2_2"/>
                <geom class="collision" size="0.04 0.06" pos="0 0 0.04"/>
                <geom class="collision" size="0.038 0.045" pos="0 0.026 0.085" quat="0.707107 0.707107 0 0"/>
                <body name="wrist_3_link" pos="0 0 0.085">
                  <inertial pos="0 0 -0.02" quat="0.5 0.5 -0.5 0.5" mass="0.26" diaginertia="0.0001792 0.000136267 0.000136267"/>
                  <joint name="robot0:wrist_3_joint" class="size0" pos="0 0 0" axis="0 1 0"/>
                  <geom class="visual" pos="0 0 0" quat="0.707107 0.707107 0 0" material="linkgray" mesh="wrist3"/>
                  <geom class="eef_collision" size="0.04 0.02" pos="0 0.08 0" quat="0.707107 0.707107 0 0"/>
                  <site name="attachment_site" pos="0 0.1 0" quat="-0.707107 0.707107 0 0"/>
                  <body name="wrist_3_linkbase_mountgripper" childclass="wrist_3_link2f140gripper" pos="0 0.107 0" quat="-0.707107 0.707107 0 0" gravcomp="1">
                    <geom class="wrist_3_linkvisualgripper" material="wrist_3_linkblackgripper" mesh="wrist_3_linkbase_mountgripper"/>
                    <geom class="wrist_3_linkcollisiongripper" mesh="wrist_3_linkbase_mountgripper"/>
                    <site name="wrist_3_linkgrasp_sitegripper" pos="0 0 0.17" quat="0.707107 0 0 -0.707107" rgba="0 1 0 1"/>
                    <body name="wrist_3_linkbasegripper" pos="0 0 0.0038" quat="0.707107 0 0 -0.707107" gravcomp="1">
                      <inertial pos="0 -2.70394e-05 0.0354675" quat="0.999999 -0.00152849 0 0" mass="0.777441" diaginertia="0.000260285 0.000225381 0.000152708"/>
                      <geom class="wrist_3_linkvisualgripper" material="wrist_3_linkblackgripper" mesh="wrist_3_linkbasegripper"/>
                      <geom class="wrist_3_linkcollisiongripper" mesh="wrist_3_linkbasegripper"/>
                      <body name="wrist_3_linkright_drivergripper" pos="0 0.030601 0.054905" quat="0 0 0.911903 0.410405" gravcomp="1">
                        <joint name="wrist_3_linkright_driver_jointgripper" class="wrist_3_linkdrivergripper" pos="0 0 0" axis="1 0 0"/>
                        <geom class="wrist_3_linkvisualgripper" material="wrist_3_linkgraygripper" mesh="wrist_3_linkdrivergripper"/>
                        <geom class="wrist_3_linkcollisiongripper" mesh="wrist_3_linkdrivergripper"/>
                        <body name="wrist_3_linkright_couplergripper" pos="0 0.01822 0.026001" gravcomp="1">
                          <inertial pos="0.000163875 0.0458404 -0.0117804" quat="0.881368 0.472423 -0.0024451 -0.000996122" mass="0.0311462" diaginertia="2.96023e-05 2.79814e-05 4.39017e-06"/>
                          <joint name="wrist_3_linkright_coupler_jointgripper" class="wrist_3_linkcouplergripper" pos="0 0 0" axis="1 0 0"/>
                          <geom class="wrist_3_linkvisualgripper" material="wrist_3_linkblackgripper" mesh="wrist_3_linkcouplergripper"/>
                          <geom class="wrist_3_linkcollisiongripper" mesh="wrist_3_linkcouplergripper"/>
                        </body>
                      </body>
                      <body name="wrist_3_linkright_spring_linkgripper" pos="0 0.0127 0.06142" quat="0 0 -0.913546 -0.406736" gravcomp="1">
                        <inertial pos="0.000123012 0.0507851 0.00103969" quat="0.497203 0.502496 -0.507943 0.492221" mass="0.0271177" diaginertia="2.83809e-05 2.61936e-05 2.81319e-06"/>
                        <joint name="wrist_3_linkright_spring_link_jointgripper" class="wrist_3_linkspring_linkgripper" pos="0 0 0" axis="1 0 0" springref="-25.62"/>
                        <geom class="wrist_3_linkvisualgripper" material="wrist_3_linkblackgripper" mesh="wrist_3_linkspring_linkgripper"/>
                        <geom class="wrist_3_linkcollisiongripper" mesh="wrist_3_linkspring_linkgripper"/>
                        <body name="wrist_3_linkright_followergripper" pos="0 0.107454 0.0145185" quat="0.935013 -0.354613 0 0" gravcomp="1">
                          <inertial pos="0.000119314 0.0339244 -0.021841" quat="0.545437 0.430197 -0.442938 0.566776" mass="0.0261503" diaginertia="1.62408e-05 1.59131e-05 2.38936e-06"/>
                          <joint name="wrist_3_linkright_follower_jointgripper" class="wrist_3_linkfollowergripper" pos="0 0.005 -0.0175" axis="1 0 0"/>
                          <geom class="wrist_3_linkvisualgripper" material="wrist_3_linkblackgripper" mesh="wrist_3_linkfollowergripper"/>
                          <geom class="wrist_3_linkcollisiongripper" mesh="wrist_3_linkfollowergripper"/>
                          <geom name="wrist_3_linkright_pad1gripper" class="wrist_3_linkpad_box1gripper" pos="0 0.0457554 -0.0272203" mass="0"/>
                          <body name="wrist_3_linkright_padgripper" pos="0 0.012 -0.0276" quat="0.707107 -0.707107 0 0" gravcomp="1">
                            <inertial pos="0 -0.0025 0.0185" quat="0.707107 0 0 0.707107" mass="0.0035" diaginertia="4.73958e-07 3.64583e-07 1.23958e-07"/>
                            <geom class="wrist_3_linkvisualgripper" mesh="wrist_3_linkpadgripper"/>
                          </body>
                        </body>
                      </body>
                      <body name="wrist_3_linkleft_drivergripper" pos="0 -0.0306011 0.054904" quat="0.410405 0.911903 0 0" gravcomp="1">
                        <joint name="wrist_3_linkleft_driver_jointgripper" class="wrist_3_linkdrivergripper" pos="0 0 0" axis="1 0 0"/>
                        <geom class="wrist_3_linkvisualgripper" material="wrist_3_linkgraygripper" mesh="wrist_3_linkdrivergripper"/>
                        <geom class="wrist_3_linkcollisiongripper" mesh="wrist_3_linkdrivergripper"/>
                        <body name="wrist_3_linkleft_couplergripper" pos="0 0.01822 0.026001" gravcomp="1">
                          <inertial pos="0.000163875 0.0458404 -0.0117804" quat="0.881368 0.472423 -0.0024451 -0.000996122" mass="0.0311462" diaginertia="2.96023e-05 2.79814e-05 4.39017e-06"/>
                          <joint name="wrist_3_linkleft_coupler_jointgripper" class="wrist_3_linkcouplergripper" pos="0 0 0" axis="1 0 0"/>
                          <geom class="wrist_3_linkvisualgripper" material="wrist_3_linkblackgripper" mesh="wrist_3_linkcouplergripper"/>
                          <geom class="wrist_3_linkcollisiongripper" mesh="wrist_3_linkcouplergripper"/>
                        </body>
                      </body>
                      <body name="wrist_3_linkleft_spring_linkgripper" pos="0 -0.0127 0.06142" quat="0.410405 0.911903 0 0" gravcomp="1">
                        <inertial pos="0.000123012 0.0507851 0.00103969" quat="0.497203 0.502496 -0.507943 0.492221" mass="0.0271177" diaginertia="2.83809e-05 2.61936e-05 2.81319e-06"/>
                        <joint name="wrist_3_linkleft_spring_link_jointgripper" class="wrist_3_linkspring_linkgripper" pos="0 0 0" axis="1 0 0" springref="-25.62"/>
                        <geom class="wrist_3_linkvisualgripper" material="wrist_3_linkblackgripper" mesh="wrist_3_linkspring_linkgripper"/>
                        <geom class="wrist_3_linkcollisiongripper" mesh="wrist_3_linkspring_linkgripper"/>
                        <body name="wrist_3_linkleft_followergripper" pos="0 0.107454 0.0145185" quat="0.935013 -0.354613 0 0" gravcomp="1">
                          <inertial pos="0.000119314 0.0339244 -0.021841" quat="0.545437 0.430197 -0.442938 0.566776" mass="0.0261503" diaginertia="1.62408e-05 1.59131e-05 2.38936e-06"/>
                          <joint name="wrist_3_linkleft_follower_jointgripper" class="wrist_3_linkfollowergripper" pos="0 0.005 -0.0175" axis="1 0 0"/>
                          <geom class="wrist_3_linkvisualgripper" material="wrist_3_linkblackgripper" mesh="wrist_3_linkfollowergripper"/>
                          <geom class="wrist_3_linkcollisiongripper" mesh="wrist_3_linkfollowergripper"/>
                          <geom name="wrist_3_linkleft_pad1gripper" class="wrist_3_linkpad_box1gripper" pos="0 0.0457554 -0.0272203" mass="0"/>
                          <body name="wrist_3_linkleft_padgripper" pos="0 0.012 -0.0276" quat="0.707107 -0.707107 0 0" gravcomp="1">
                            <inertial pos="0 -0.0025 0.0185" quat="0.707107 0 0 0.707107" mass="0.0035" diaginertia="4.73958e-07 3.64583e-07 1.23958e-07"/>
                            <geom class="wrist_3_linkvisualgripper" mesh="wrist_3_linkpadgripper"/>
                          </body>
                        </body>
                      </body>
                    </body>
                  </body>
                </body>
              </body>
            </body>
          </body>
        </body>
      </body>
    </body>
  </worldbody>

  <contact>
    <exclude body1="wrist_3_linkbasegripper" body2="wrist_3_linkright_drivergripper"/>
    <exclude body1="wrist_3_linkbasegripper" body2="wrist_3_linkright_spring_linkgripper"/>
    <exclude body1="wrist_3_linkbasegripper" body2="wrist_3_linkleft_drivergripper"/>
    <exclude body1="wrist_3_linkbasegripper" body2="wrist_3_linkleft_spring_linkgripper"/>
    <exclude body1="wrist_3_linkright_drivergripper" body2="wrist_3_linkright_spring_linkgripper"/>
    <exclude body1="wrist_3_linkright_couplergripper" body2="wrist_3_linkright_spring_linkgripper"/>
    <exclude body1="wrist_3_linkright_couplergripper" body2="wrist_3_linkright_followergripper"/>
    <exclude body1="wrist_3_linkright_spring_linkgripper" body2="wrist_3_linkleft_spring_linkgripper"/>
    <exclude body1="wrist_3_linkright_spring_linkgripper" body2="wrist_3_linkleft_followergripper"/>
    <exclude body1="wrist_3_linkright_followergripper" body2="wrist_3_linkleft_spring_linkgripper"/>
    <exclude body1="wrist_3_linkright_followergripper" body2="wrist_3_linkleft_followergripper"/>
    <exclude body1="wrist_3_linkleft_drivergripper" body2="wrist_3_linkleft_spring_linkgripper"/>
    <exclude body1="wrist_3_linkleft_couplergripper" body2="wrist_3_linkleft_spring_linkgripper"/>
    <exclude body1="wrist_3_linkleft_couplergripper" body2="wrist_3_linkleft_followergripper"/>
  </contact>

  <equality>
    <connect body1="wrist_3_linkright_followergripper" body2="wrist_3_linkright_couplergripper" anchor="0 0 0" solref="0.005" solimp="0.95 0.99"/>
    <connect body1="wrist_3_linkleft_followergripper" body2="wrist_3_linkleft_couplergripper" anchor="0 0 0" solref="0.005" solimp="0.95 0.99"/>
    <joint joint1="wrist_3_linkright_driver_jointgripper" joint2="wrist_3_linkleft_driver_jointgripper" polycoef="0 1 0 0 0" solref="0.005" solimp="0.95 0.99"/>
  </equality>

  <tendon>
    <fixed name="wrist_3_linksplitgripper">
      <joint joint="wrist_3_linkright_driver_jointgripper" coef="-0.5"/>
      <joint joint="wrist_3_linkleft_driver_jointgripper" coef="-0.5"/>
    </fixed>
  </tendon>

  <actuator>
    <general name="shoulder_pan" class="size2" joint="robot0:shoulder_pan_joint"/>
    <general name="shoulder_lift" class="size2" joint="robot0:shoulder_lift_joint"/>
    <general name="elbow" class="size1" joint="robot0:elbow_joint"/>
    <general name="wrist_1" class="size0" joint="robot0:wrist_1_joint"/>
    <general name="wrist_2" class="size0" joint="robot0:wrist_2_joint"/>
    <general name="wrist_3" class="size0" joint="robot0:wrist_3_joint"/>
    <general name="wrist_3_linkfingers_actuatorgripper" class="wrist_3_link2f140gripper" tendon="wrist_3_linksplitgripper" ctrlrange="0 255" forcerange="-5 5" gainprm="0.313725" biasprm="0 -100 -10"/>
  </actuator>

  <keyframe>
    <key name="home" qpos="-1.5708 -1.5708 1.5708 -1.5708 -1.5708 0 0 0 0 0 0 0 0 0" ctrl="-1.5708 -1.5708 1.5708 -1.5708 -1.5708 0 0"/>
    <key name="wrist_3_linkreadygripper"/>
  </keyframe>
</mujoco>
